2020-11-02 07:46:22,695:DEBUG:certbot._internal.main:certbot version: 1.9.0
2020-11-02 07:46:22,695:DEBUG:certbot._internal.main:Arguments: ['--webroot', '--webroot-path=/usr/share/nginx/html/letsencrypt', '--email', 'rpi.iot.2020@gmail.com', '--agree-tos', '--no-eff-email', '-d', 'rpi-iot.duckdns.org']
2020-11-02 07:46:22,696:DEBUG:certbot._internal.main:Discovered plugins: PluginsRegistry(PluginEntryPoint#manual,PluginEntryPoint#null,PluginEntryPoint#standalone,PluginEntryPoint#webroot)
2020-11-02 07:46:22,755:DEBUG:certbot._internal.log:Root logging level set at 20
2020-11-02 07:46:22,756:INFO:certbot._internal.log:Saving debug log to /var/log/letsencrypt/letsencrypt.log
2020-11-02 07:46:22,758:DEBUG:certbot._internal.plugins.selection:Requested authenticator webroot and installer None
2020-11-02 07:46:22,771:DEBUG:certbot._internal.plugins.selection:Single candidate plugin: * webroot
Description: Place files in webroot directory
Interfaces: IAuthenticator, IPlugin
Entry point: webroot = certbot._internal.plugins.webroot:Authenticator
Initialized: <certbot._internal.plugins.webroot.Authenticator object at 0x7fc1a0e1a940>
Prep: True
2020-11-02 07:46:22,773:DEBUG:certbot._internal.plugins.selection:Selected authenticator <certbot._internal.plugins.webroot.Authenticator object at 0x7fc1a0e1a940> and installer None
2020-11-02 07:46:22,773:INFO:certbot._internal.plugins.selection:Plugins selected: Authenticator webroot, Installer None
2020-11-02 07:46:22,783:DEBUG:certbot._internal.main:Picked account: <Account(RegistrationResource(body=Registration(key=None, contact=(), agreement=None, status=None, terms_of_service_agreed=None, only_return_existing=None, external_account_binding=None), uri='https://acme-v02.api.letsencrypt.org/acme/acct/101055913', new_authzr_uri=None, terms_of_service=None), 331f70515e28b731b0aa2f62a3c69731, Meta(creation_dt=datetime.datetime(2020, 11, 2, 4, 42, 7, tzinfo=<UTC>), creation_host='7a51cc79cdad', register_to_eff=None))>
2020-11-02 07:46:22,786:DEBUG:acme.client:Sending GET request to https://acme-v02.api.letsencrypt.org/directory.
2020-11-02 07:46:22,790:DEBUG:urllib3.connectionpool:Starting new HTTPS connection (1): acme-v02.api.letsencrypt.org:443
2020-11-02 07:46:23,653:DEBUG:urllib3.connectionpool:https://acme-v02.api.letsencrypt.org:443 "GET /directory HTTP/1.1" 200 658
2020-11-02 07:46:23,655:DEBUG:acme.client:Received response:
HTTP 200
Server: nginx
Date: Mon, 02 Nov 2020 07:46:23 GMT
Content-Type: application/json
Content-Length: 658
Connection: keep-alive
Cache-Control: public, max-age=0, no-cache
X-Frame-Options: DENY
Strict-Transport-Security: max-age=604800

{
  "ioVVwt1YtvQ": "https://community.letsencrypt.org/t/adding-random-entries-to-the-directory/33417",
  "keyChange": "https://acme-v02.api.letsencrypt.org/acme/key-change",
  "meta": {
    "caaIdentities": [
      "letsencrypt.org"
    ],
    "termsOfService": "https://letsencrypt.org/documents/LE-SA-v1.2-November-15-2017.pdf",
    "website": "https://letsencrypt.org"
  },
  "newAccount": "https://acme-v02.api.letsencrypt.org/acme/new-acct",
  "newNonce": "https://acme-v02.api.letsencrypt.org/acme/new-nonce",
  "newOrder": "https://acme-v02.api.letsencrypt.org/acme/new-order",
  "revokeCert": "https://acme-v02.api.letsencrypt.org/acme/revoke-cert"
}
2020-11-02 07:46:23,681:DEBUG:urllib3.connectionpool:Starting new HTTP connection (1): ocsp.int-x3.letsencrypt.org:80
2020-11-02 07:46:23,736:DEBUG:urllib3.connectionpool:http://ocsp.int-x3.letsencrypt.org:80 "POST / HTTP/1.1" 200 527
2020-11-02 07:46:23,742:DEBUG:certbot.ocsp:OCSP response for certificate /etc/letsencrypt/archive/rpi-iot.duckdns.org/cert1.pem is signed by the certificate's issuer.
2020-11-02 07:46:23,751:DEBUG:certbot.ocsp:OCSP certificate status for /etc/letsencrypt/archive/rpi-iot.duckdns.org/cert1.pem is: OCSPCertStatus.GOOD
2020-11-02 07:46:23,761:INFO:certbot._internal.renewal:Cert not yet due for renewal
2020-11-02 07:46:23,763:DEBUG:certbot._internal.log:Exiting abnormally:
Traceback (most recent call last):
  File "/usr/local/bin/certbot", line 11, in <module>
    load_entry_point('certbot', 'console_scripts', 'certbot')()
  File "/opt/certbot/src/certbot/certbot/main.py", line 15, in main
    return internal_main.main(cli_args)
  File "/opt/certbot/src/certbot/certbot/_internal/main.py", line 1362, in main
    return config.func(config, plugins)
  File "/opt/certbot/src/certbot/certbot/_internal/main.py", line 1236, in certonly
    should_get_cert, lineage = _find_cert(config, domains, certname)
  File "/opt/certbot/src/certbot/certbot/_internal/main.py", line 287, in _find_cert
    action, lineage = _find_lineage_for_domains_and_certname(config, domains, certname)
  File "/opt/certbot/src/certbot/certbot/_internal/main.py", line 314, in _find_lineage_for_domains_and_certname
    return _find_lineage_for_domains(config, domains)
  File "/opt/certbot/src/certbot/certbot/_internal/main.py", line 264, in _find_lineage_for_domains
    return _handle_identical_cert_request(config, ident_names_cert)
  File "/opt/certbot/src/certbot/certbot/_internal/main.py", line 216, in _handle_identical_cert_request
    response = display.menu(question, choices,
  File "/opt/certbot/src/certbot/certbot/display/util.py", line 153, in menu
    code, selection = self._get_valid_int_ans(len(choices))
  File "/opt/certbot/src/certbot/certbot/display/util.py", line 411, in _get_valid_int_ans
    ans = input_with_timeout(input_msg)
  File "/opt/certbot/src/certbot/certbot/display/util.py", line 85, in input_with_timeout
    raise EOFError
EOFError
2020-11-02 07:46:23,767:ERROR:certbot._internal.log:An unexpected error occurred:
2020-11-02 07:46:23,767:ERROR:certbot._internal.log:EOFError
